Workbook
Name AUD: #REF!
Name AUD: #REF!
Name AUD: #REF!
Name CAD: #REF!
Name CAD: #REF!
Name CAD: #REF!
Name Capital_raise: [1]inputs!$K$6
Name col: #REF!
Name col: #REF!
Name col: #REF!
Name ddd: Word
Name ddd: Word
Name ddd: Word
Name dealprice: #REF!
Name dealprice: #REF!
Name dealprice: #REF!
Name DocType: Word
Name DocType: Word
Name DocType: Word
Name EUR: #REF!
Name EUR: #REF!
Name EUR: #REF!
Name fff: Word
Name fff: Word
Name fff: Word
Name GBP: #REF!
Name GBP: #REF!
Name GBP: #REF!
Name gg: Word
Name gg: Word
Name gg: Word
Name HKD: #REF!
Name HKD: #REF!
Name HKD: #REF!
Name MonitorCol: 1
Name MonitorRow: 1
Name MonthNames: {"Jan","Feb","Mar","Apr","May","Jun","Jul","Aug","Sep","Oct","Nov","Dec";"January","February","March","April","May","June","July","August","September","October","November","December"}
Name pbFileName: MID(CELL("filename"),FIND("[",CELL("FILENAME"))+1,(FIND("]",CELL("FILENAME"))) - (FIND("[",CELL("FILENAME"))+1))
Name pbPrinterFormat: "\\SGB24831\P0047496 on Ne05:"
Name pbStartPageNumber: 1
Name pbUpdatePageNumbering: TRUE
Name row: #REF!
Name row: #REF!
Name row: #REF!
Name SEK: #REF!
Name SEK: #REF!
Name SEK: #REF!
Name SGD: #REF!
Name SGD: #REF!
Name SGD: #REF!
Name ticker: #REF!
Name ticker: #REF!
Name ticker: #REF!
Name TickerCell: #REF!
Name TickerCell: #REF!
Name TickerCell: #REF!

Sheet model
B1: Standard Operating Model
B3: Period | E3: 41274 | F3: 41639 | G3: 42004 | H3: 42369 | I3: 42735 | J3: 43100 | K3: 43465 | L3: 43830 | M3: 44196 | N3: 44561 | O3: 44926 | P3: 45291
B5: ASSUMPTIONS
A6: X
E8: =E$3 -> 41274 | F8: =F$3 -> 41639 | G8: =G$3 -> 42004 | H8: =H$3 -> 42369 | I8: =I$3 -> 42735 | J8: =J$3 -> 43100 | K8: =K$3 -> 43465 | L8: =L$3 -> 43830 | ... P8: =P$3 -> 45291
B10: Loans
B11: New Volume | F11: 400 | G11: =F11 -> 400 | H11: =G11 -> 400 | I11: =H11 -> 400 | J11: =I11 -> 400 | K11: =J11 -> 400 | L11: =K11 -> 400 | M11: =L11 -> 400 | N11: =M11 -> 400 | ... P11: =O11 -> 400
B12: Amortization/Prepayment | F12: 0.2 | G12: =F12 -> 0.2 | H12: =G12 -> 0.2 | I12: =H12 -> 0.2 | J12: =I12 -> 0.2 | K12: =J12 -> 0.2 | L12: =K12 -> 0.2 | M12: =L12 -> 0.2 | N12: =M12 -> 0.2 | ... P12: =O12 -> 0.2
B13: Net Charge-Offs | F13: 0.01 | G13: =F13 -> 0.01 | H13: =G13 -> 0.01 | I13: =H13 -> 0.01 | J13: =I13 -> 0.01 | K13: =J13 -> 0.01 | L13: =K13 -> 0.01 | M13: =L13 -> 0.01 | N13: =M13 -> 0.01 | ... P13: =O13 -> 0.01
B14: Loan Yield | F14: 0.055 | G14: =F14 -> 0.055 | H14: =G14 -> 0.055 | I14: =H14 -> 0.055 | J14: =I14 -> 0.055 | K14: =J14 -> 0.055 | L14: =K14 -> 0.055 | M14: =L14 -> 0.055 | N14: =M14 -> 0.055 | ... P14: =O14 -> 0.055
B15: Roll-Forward:
B16: BOP Balance | F16: =E92 -> 1350 | G16: =F20 -> 1466.5 | H16: =G20 -> 1558.535 | I16: =H20 -> 1631.2426 | J16: =I20 -> 1688.6817 | K16: =J20 -> 1734.0585 | L16: =K20 -> 1769.9062 | M16: =L20 -> 1798.2259 | N16: =M20 -> 1820.5985 | ... P16: =O20 -> 1852.2355
B17: Originations | F17: =F11 -> 400 | G17: =G11 -> 400 | H17: =H11 -> 400 | I17: =I11 -> 400 | J17: =J11 -> 400 | K17: =K11 -> 400 | L17: =L11 -> 400 | M17: =M11 -> 400 | ... P17: =P11 -> 400
B18: Amortization/Prepayment | F18: =-F16*F12 -> -270 | G18: =-G16*G12 -> -293.3 | H18: =-H16*H12 -> -311.707 | I18: =-I16*I12 -> -326.24853 | J18: =-J16*J12 -> -337.73634 | K18: =-K16*K12 -> -346.81171 | L18: =-L16*L12 -> -353.98125 | M18: =-M16*M12 -> -359.64519 | ... P18: =-P16*P12 -> -370.4471
B19: Net-Charge Offs | F19: =-F16*F13 -> -13.5 | G19: =-G16*G13 -> -14.665 | H19: =-H16*H13 -> -15.58535 | I19: =-I16*I13 -> -16.312427 | J19: =-J16*J13 -> -16.886817 | K19: =-K16*K13 -> -17.340585 | L19: =-L16*L13 -> -17.699062 | M19: =-M16*M13 -> -17.982259 | ... P19: =-P16*P13 -> -18.522355
B20: EOP Balance | F20: =SUM(F16:F19) -> 1466.5 | G20: =SUM(G16:G19) -> 1558.535 | H20: =SUM(H16:H19) -> 1631.2426 | I20: =SUM(I16:I19) -> 1688.6817 | J20: =SUM(J16:J19) -> 1734.0585 | K20: =SUM(K16:K19) -> 1769.9062 | L20: =SUM(L16:L19) -> 1798.2259 | M20: =SUM(M16:M19) -> 1820.5985 | ... P20: =SUM(P16:P19) -> 1863.2661
B21: Average Balance | F21: =AVERAGE(F20,F16) -> 1408.25 | G21: =AVERAGE(G20,G16) -> 1512.5175 | H21: =AVERAGE(H20,H16) -> 1594.8888 | I21: =AVERAGE(I20,I16) -> 1659.9622 | J21: =AVERAGE(J20,J16) -> 1711.3701 | K21: =AVERAGE(K20,K16) -> 1751.9824 | L21: =AVERAGE(L20,L16) -> 1784.0661 | M21: =AVERAGE(M20,M16) -> 1809.4122 | ... P21: =AVERAGE(P20,P16) -> 1857.7508
B22: Interest Income | F22: =F21*F14 -> 77.45375 | G22: =G21*G14 -> 83.188462 | H22: =H21*H14 -> 87.718885 | I22: =I21*I14 -> 91.297919 | J22: =J21*J14 -> 94.125356 | K22: =K21*K14 -> 96.359032 | L22: =L21*L14 -> 98.123635 | M22: =M21*M14 -> 99.517672 | ... P22: =P21*P14 -> 102.17629
B24: Securities and Cash
B25: Securities as % of Assets | E25: =E27/E100 -> 0.16620499 | F25: 0.2 | G25: =F25 -> 0.2 | H25: =G25 -> 0.2 | I25: =H25 -> 0.2 | J25: =I25 -> 0.2 | K25: =J25 -> 0.2 | L25: =K25 -> 0.2 | M25: =L25 -> 0.2 | N25: =M25 -> 0.2 | ... P25: =O25 -> 0.2
B26: Securities Yield | E26: Opening | F26: 0.03 | G26: =F26 -> 0.03 | H26: =G26 -> 0.03 | I26: =H26 -> 0.03 | J26: =I26 -> 0.03 | K26: =J26 -> 0.03 | L26: =K26 -> 0.03 | M26: =L26 -> 0.03 | N26: =M26 -> 0.03 | ... P26: =O26 -> 0.03
B27: Securities Balance | E27: =E91 -> 300 | F27: =F91 -> 405.75063 | G27: =G91 -> 429.30674 | H27: =H91 -> 448.12135 | I27: =I91 -> 463.19427 | J27: =J91 -> 475.31545 | K27: =K91 -> 485.10902 | L27: =L91 -> 493.06813 | ... P27: =P91 -> 513.22689
B28: Average Balance | F28: =AVERAGE(E27:F27) -> 352.87531 | G28: =AVERAGE(F27:G27) -> 417.52868 | H28: =AVERAGE(G27:H27) -> 438.71405 | I28: =AVERAGE(H27:I27) -> 455.65781 | J28: =AVERAGE(I27:J27) -> 469.25486 | K28: =AVERAGE(J27:K27) -> 480.21223 | L28: =AVERAGE(K27:L27) -> 489.08858 | M28: =AVERAGE(L27:M27) -> 496.3253 | ... P28: =AVERAGE(O27:P27) -> 511.33545
B29: Interest Income | F29: =F26*F28 -> 10.586259 | G29: =G26*G28 -> 12.525861 | H29: =H26*H28 -> 13.161421 | I29: =I26*I28 -> 13.669734 | J29: =J26*J28 -> 14.077646 | K29: =K26*K28 -> 14.406367 | L29: =L26*L28 -> 14.672657 | M29: =M26*M28 -> 14.889759 | ... P29: =P26*P28 -> 15.340063
B31: Cash Yield | E31: Opening | F31: 0.0025 | G31: =F31 -> 0.0025 | H31: =G31 -> 0.0025 | I31: =H31 -> 0.0025 | J31: =I31 -> 0.0025 | K31: =J31 -> 0.0025 | L31: =K31 -> 0.0025 | M31: =L31 -> 0.0025 | N31: =M31 -> 0.0025 | ... P31: =O31 -> 0.0025
B32: Securities Balance | E32: =E90 -> 75 | F32: =F90 -> 76.5 | G32: =G90 -> 78.03 | H32: =H90 -> 79.5906 | I32: =I90 -> 81.182412 | J32: =J90 -> 82.80606 | K32: =K90 -> 84.462181 | L32: =L90 -> 86.151425 | ... P32: =P90 -> 93.253073
B33: Average Balance | F33: =AVERAGE(E32:F32) -> 75.75 | G33: =AVERAGE(F32:G32) -> 77.265 | H33: =AVERAGE(G32:H32) -> 78.8103 | I33: =AVERAGE(H32:I32) -> 80.386506 | J33: =AVERAGE(I32:J32) -> 81.994236 | K33: =AVERAGE(J32:K32) -> 83.634121 | L33: =AVERAGE(K32:L32) -> 85.306803 | M33: =AVERAGE(L32:M32) -> 87.012939 | ... P33: =AVERAGE(O32:P32) -> 92.338827
B34: Interest Income | F34: =F31*F33 -> 0.189375 | G34: =G31*G33 -> 0.1931625 | H34: =H31*H33 -> 0.19702575 | I34: =I31*I33 -> 0.20096627 | J34: =J31*J33 -> 0.20498559 | K34: =K31*K33 -> 0.2090853 | L34: =L31*L33 -> 0.21326701 | M34: =M31*M33 -> 0.21753235 | ... P34: =P31*P33 -> 0.23084707
B36: Loan Loss Reserve
B37: Reserve/Loans | F37: 0.015 | G37: =F37 -> 0.015 | H37: =G37 -> 0.015 | I37: =H37 -> 0.015 | J37: =I37 -> 0.015 | K37: =J37 -> 0.015 | L37: =K37 -> 0.015 | M37: =L37 -> 0.015 | N37: =M37 -> 0.015 | ... P37: =O37 -> 0.015
B38: Roll-Forward:
B39: BOP Balance | F39: =E93 -> 20 | G39: =F42 -> 21.9975 | H39: =G42 -> 23.378025 | I39: =H42 -> 24.46864 | J39: =I42 -> 25.330225 | K39: =J42 -> 26.010878 | L39: =K42 -> 26.548594 | M39: =L42 -> 26.973389 | N39: =M42 -> 27.308977 | ... P39: =O42 -> 27.783533
B40: Loan Loss Provision | F40: =F42-F39-F41 -> 15.4975 | G40: =G42-G39-G41 -> 16.045525 | H40: =H42-H39-H41 -> 16.675965 | I40: =I42-I39-I41 -> 17.174012 | J40: =J42-J39-J41 -> 17.56747 | K40: =K42-K39-K41 -> 17.878301 | L40: =L42-L39-L41 -> 18.123858 | M40: =M42-M39-M41 -> 18.317848 | ... P40: =P42-P39-P41 -> 18.687813
B41: Net Charge-Offs | F41: =F19 -> -13.5 | G41: =G19 -> -14.665 | H41: =H19 -> -15.58535 | I41: =I19 -> -16.312427 | J41: =J19 -> -16.886817 | K41: =K19 -> -17.340585 | L41: =L19 -> -17.699062 | M41: =M19 -> -17.982259 | ... P41: =P19 -> -18.522355
B42: EOP Balance | F42: =F37*F20 -> 21.9975 | G42: =G37*G20 -> 23.378025 | H42: =H37*H20 -> 24.46864 | I42: =I37*I20 -> 25.330225 | J42: =J37*J20 -> 26.010878 | K42: =K37*K20 -> 26.548594 | L42: =L37*L20 -> 26.973389 | M42: =M37*M20 -> 27.308977 | ... P42: =P37*P20 -> 27.948991
A44: X | B44: Funding
B45: Deposit Growth | F45: 0.05 | G45: =F45 -> 0.05 | H45: =G45 -> 0.05 | I45: =H45 -> 0.05 | J45: =I45 -> 0.05 | K45: =J45 -> 0.05 | L45: =K45 -> 0.05 | M45: =L45 -> 0.05 | N45: =M45 -> 0.05 | ... P45: =O45 -> 0.05
B46: Deposit Cost | E46: Opening | F46: 0.005 | G46: =F46 -> 0.005 | H46: =G46 -> 0.005 | I46: =H46 -> 0.005 | J46: =I46 -> 0.005 | K46: =J46 -> 0.005 | L46: =K46 -> 0.005 | M46: =L46 -> 0.005 | N46: =M46 -> 0.005 | ... P46: =O46 -> 0.005
B47: Deposit Balance | E47: =E103 -> 1500 | F47: =E47*(1+F45) -> 1575 | G47: =F47*(1+G45) -> 1653.75 | H47: =G47*(1+H45) -> 1736.4375 | I47: =H47*(1+I45) -> 1823.2594 | J47: =I47*(1+J45) -> 1914.4223 | K47: =J47*(1+K45) -> 2010.1435 | L47: =K47*(1+L45) -> 2110.6506 | M47: =L47*(1+M45) -> 2216.1832 | ... P47: =O47*(1+P45) -> 2565.509
B48: Average Balance | F48: =AVERAGE(E47:F47) -> 1537.5 | G48: =AVERAGE(F47:G47) -> 1614.375 | H48: =AVERAGE(G47:H47) -> 1695.0938 | I48: =AVERAGE(H47:I47) -> 1779.8484 | J48: =AVERAGE(I47:J47) -> 1868.8409 | K48: =AVERAGE(J47:K47) -> 1962.2829 | L48: =AVERAGE(K47:L47) -> 2060.397 | M48: =AVERAGE(L47:M47) -> 2163.4169 | ... P48: =AVERAGE(O47:P47) -> 2504.4255
...

Sheet loan
B1: Standard Operating Model
B3: LOAN SCHEDULE
A4: X
E6: =model!E3 -> 41274 | F6: =model!F3 -> 41639 | G6: =model!G3 -> 42004 | H6: =model!H3 -> 42369 | I6: =model!I3 -> 42735 | J6: =model!J3 -> 43100 | K6: =model!K3 -> 43465 | L6: =model!L3 -> 43830 | ... P6: =model!P3 -> 45291
B8: Scheduled Amortization
C10: Maturity
B11: {=TRANSPOSE($E$6:$P$6)} -> 41274 | C11: 5 | E11: =-$C45/$C11*0.5 -> -20 | F11: =IF((E45+F28)<$C45/$C11,-(E45+F28),-$C45/$C11) -> -40 | G11: =IF((F45+G28)<$C45/$C11,-(F45+G28),-$C45/$C11) -> -40 | H11: =IF((G45+H28)<$C45/$C11,-(G45+H28),-$C45/$C11) -> -40 | I11: =IF((H45+I28)<$C45/$C11,-(H45+I28),-$C45/$C11) -> -40 | J11: =IF((I45+J28)<$C45/$C11,-(I45+J28),-$C45/$C11) -> -14.187419 | K11: =IF((J45+K28)<$C45/$C11,-(J45+K28),-$C45/$C11) -> 0 | L11: =IF((K45+L28)<$C45/$C11,-(K45+L28),-$C45/$C11) -> 0 | M11: =IF((L45+M28)<$C45/$C11,-(L45+M28),-$C45/$C11) -> 0 | ... P11: =IF((O45+P28)<$C45/$C11,-(O45+P28),-$C45/$C11) -> 0
B12: 41639 | C12: =C11 -> 5 | F12: =-$C46/$C12*0.5 -> -20 | G12: =IF((F46+G29)<$C46/$C12,-(F46+G29),-$C46/$C12) -> -40 | H12: =IF((G46+H29)<$C46/$C12,-(G46+H29),-$C46/$C12) -> -40 | I12: =IF((H46+I29)<$C46/$C12,-(H46+I29),-$C46/$C12) -> -40 | J12: =IF((I46+J29)<$C46/$C12,-(I46+J29),-$C46/$C12) -> -40 | K12: =IF((J46+K29)<$C46/$C12,-(J46+K29),-$C46/$C12) -> -14.187419 | L12: =IF((K46+L29)<$C46/$C12,-(K46+L29),-$C46/$C12) -> 0 | M12: =IF((L46+M29)<$C46/$C12,-(L46+M29),-$C46/$C12) -> 0 | N12: =IF((M46+N29)<$C46/$C12,-(M46+N29),-$C46/$C12) -> 0 | ... P12: =IF((O46+P29)<$C46/$C12,-(O46+P29),-$C46/$C12) -> 0
B13: 42004 | C13: =C12 -> 5 | G13: =-$C47/$C13*0.5 -> -20 | H13: =IF((G47+H30)<$C47/$C13,-(G47+H30),-$C47/$C13) -> -40 | I13: =IF((H47+I30)<$C47/$C13,-(H47+I30),-$C47/$C13) -> -40 | J13: =IF((I47+J30)<$C47/$C13,-(I47+J30),-$C47/$C13) -> -40 | K13: =IF((J47+K30)<$C47/$C13,-(J47+K30),-$C47/$C13) -> -40 | L13: =IF((K47+L30)<$C47/$C13,-(K47+L30),-$C47/$C13) -> -14.187419 | M13: =IF((L47+M30)<$C47/$C13,-(L47+M30),-$C47/$C13) -> 0 | N13: =IF((M47+N30)<$C47/$C13,-(M47+N30),-$C47/$C13) -> 0 | O13: =IF((N47+O30)<$C47/$C13,-(N47+O30),-$C47/$C13) -> 0 | P13: =IF((O47+P30)<$C47/$C13,-(O47+P30),-$C47/$C13) -> 0
B14: 42369 | C14: =C13 -> 5 | H14: =-$C48/$C14*0.5 -> -20 | I14: =IF((H48+I31)<$C48/$C14,-(H48+I31),-$C48/$C14) -> -40 | J14: =IF((I48+J31)<$C48/$C14,-(I48+J31),-$C48/$C14) -> -40 | K14: =IF((J48+K31)<$C48/$C14,-(J48+K31),-$C48/$C14) -> -40 | L14: =IF((K48+L31)<$C48/$C14,-(K48+L31),-$C48/$C14) -> -40 | M14: =IF((L48+M31)<$C48/$C14,-(L48+M31),-$C48/$C14) -> -14.187419 | N14: =IF((M48+N31)<$C48/$C14,-(M48+N31),-$C48/$C14) -> 0 | O14: =IF((N48+O31)<$C48/$C14,-(N48+O31),-$C48/$C14) -> 0 | P14: =IF((O48+P31)<$C48/$C14,-(O48+P31),-$C48/$C14) -> 0
B15: 42735 | C15: =C14 -> 5 | I15: =-$C49/$C15*0.5 -> -20 | J15: =IF((I49+J32)<$C49/$C15,-(I49+J32),-$C49/$C15) -> -40 | K15: =IF((J49+K32)<$C49/$C15,-(J49+K32),-$C49/$C15) -> -40 | L15: =IF((K49+L32)<$C49/$C15,-(K49+L32),-$C49/$C15) -> -40 | M15: =IF((L49+M32)<$C49/$C15,-(L49+M32),-$C49/$C15) -> -40 | N15: =IF((M49+N32)<$C49/$C15,-(M49+N32),-$C49/$C15) -> -14.187419 | O15: =IF((N49+O32)<$C49/$C15,-(N49+O32),-$C49/$C15) -> 0 | P15: =IF((O49+P32)<$C49/$C15,-(O49+P32),-$C49/$C15) -> 0
B16: 43100 | C16: =C15 -> 5 | J16: =-$C50/$C16*0.5 -> -20 | K16: =IF((J50+K33)<$C50/$C16,-(J50+K33),-$C50/$C16) -> -40 | L16: =IF((K50+L33)<$C50/$C16,-(K50+L33),-$C50/$C16) -> -40 | M16: =IF((L50+M33)<$C50/$C16,-(L50+M33),-$C50/$C16) -> -40 | N16: =IF((M50+N33)<$C50/$C16,-(M50+N33),-$C50/$C16) -> -40 | O16: =IF((N50+O33)<$C50/$C16,-(N50+O33),-$C50/$C16) -> -14.187419 | P16: =IF((O50+P33)<$C50/$C16,-(O50+P33),-$C50/$C16) -> 0
B17: 43465 | C17: =C16 -> 5 | K17: =-$C51/$C17*0.5 -> -20 | L17: =IF((K51+L34)<$C51/$C17,-(K51+L34),-$C51/$C17) -> -40 | M17: =IF((L51+M34)<$C51/$C17,-(L51+M34),-$C51/$C17) -> -40 | N17: =IF((M51+N34)<$C51/$C17,-(M51+N34),-$C51/$C17) -> -40 | O17: =IF((N51+O34)<$C51/$C17,-(N51+O34),-$C51/$C17) -> -40 | P17: =IF((O51+P34)<$C51/$C17,-(O51+P34),-$C51/$C17) -> -14.187419
B18: 43830 | C18: =C17 -> 5 | L18: =-$C52/$C18*0.5 -> -20 | M18: =IF((L52+M35)<$C52/$C18,-(L52+M35),-$C52/$C18) -> -40 | N18: =IF((M52+N35)<$C52/$C18,-(M52+N35),-$C52/$C18) -> -40 | O18: =IF((N52+O35)<$C52/$C18,-(N52+O35),-$C52/$C18) -> -40 | P18: =IF((O52+P35)<$C52/$C18,-(O52+P35),-$C52/$C18) -> -40
B19: 44196 | C19: =C18 -> 5 | M19: =-$C53/$C19*0.5 -> -20 | N19: =IF((M53+N36)<$C53/$C19,-(M53+N36),-$C53/$C19) -> -40 | O19: =IF((N53+O36)<$C53/$C19,-(N53+O36),-$C53/$C19) -> -40 | P19: =IF((O53+P36)<$C53/$C19,-(O53+P36),-$C53/$C19) -> -40
B20: 44561 | C20: =C19 -> 5 | N20: =-$C54/$C20*0.5 -> -20 | O20: =IF((N54+O37)<$C54/$C20,-(N54+O37),-$C54/$C20) -> -40 | P20: =IF((O54+P37)<$C54/$C20,-(O54+P37),-$C54/$C20) -> -40
B21: 44926 | C21: =C20 -> 5 | O21: =-$C55/$C21*0.5 -> -20 | P21: =IF((O55+P38)<$C55/$C21,-(O55+P38),-$C55/$C21) -> -40
B22: 45291 | C22: =C21 -> 5 | P22: =-$C56/$C22*0.5 -> -20
B23: Total Originations | E23: =SUM(E11:E22) -> -20 | F23: =SUM(F11:F22) -> -60 | G23: =SUM(G11:G22) -> -100 | H23: =SUM(H11:H22) -> -140 | I23: =SUM(I11:I22) -> -180 | J23: =SUM(J11:J22) -> -194.18742 | K23: =SUM(K11:K22) -> -194.18742 | L23: =SUM(L11:L22) -> -194.18742 | ... P23: =SUM(P11:P22) -> -194.18742
B25: Net Credit Losses
C27: NCOs
B28: {=TRANSPOSE($E$6:$P$6)} -> 41274 | C28: 0.01 | E28: =-($C45)*$C$28*0.5 -> -1 | F28: =-(E45)*$C$28 -> -1.79 | G28: =-(F45)*$C$28 -> -1.3721 | H28: =-(G45)*$C$28 -> -0.958379 | I28: =-(H45)*$C$28 -> -0.54879521 | J28: =-(I45)*$C$28 -> -0.14330726 | K28: =-(J45)*$C$28 -> 0 | L28: =-(K45)*$C$28 -> 0 | M28: =-(L45)*$C$28 -> 0 | ... P28: =-(O45)*$C$28 -> 0
B29: 41639 | C29: =C28 -> 0.01 | F29: =-($C46)*$C$28*0.5 -> -1 | G29: =-(F46)*$C$28 -> -1.79 | H29: =-(G46)*$C$28 -> -1.3721 | I29: =-(H46)*$C$28 -> -0.958379 | J29: =-(I46)*$C$28 -> -0.54879521 | K29: =-(J46)*$C$28 -> -0.14330726 | L29: =-(K46)*$C$28 -> 0 | M29: =-(L46)*$C$28 -> 0 | N29: =-(M46)*$C$28 -> 0 | ... P29: =-(O46)*$C$28 -> 0
B30: 42004 | C30: =C29 -> 0.01 | G30: =-($C47)*$C$28*0.5 -> -1 | H30: =-(G47)*$C$28 -> -1.79 | I30: =-(H47)*$C$28 -> -1.3721 | J30: =-(I47)*$C$28 -> -0.958379 | K30: =-(J47)*$C$28 -> -0.54879521 | L30: =-(K47)*$C$28 -> -0.14330726 | M30: =-(L47)*$C$28 -> 0 | N30: =-(M47)*$C$28 -> 0 | O30: =-(N47)*$C$28 -> 0 | P30: =-(O47)*$C$28 -> 0
B31: 42369 | C31: =C30 -> 0.01 | H31: =-($C48)*$C$28*0.5 -> -1 | I31: =-(H48)*$C$28 -> -1.79 | J31: =-(I48)*$C$28 -> -1.3721 | K31: =-(J48)*$C$28 -> -0.958379 | L31: =-(K48)*$C$28 -> -0.54879521 | M31: =-(L48)*$C$28 -> -0.14330726 | N31: =-(M48)*$C$28 -> 0 | O31: =-(N48)*$C$28 -> 0 | P31: =-(O48)*$C$28 -> 0
B32: 42735 | C32: =C31 -> 0.01 | I32: =-($C49)*$C$28*0.5 -> -1 | J32: =-(I49)*$C$28 -> -1.79 | K32: =-(J49)*$C$28 -> -1.3721 | L32: =-(K49)*$C$28 -> -0.958379 | M32: =-(L49)*$C$28 -> -0.54879521 | N32: =-(M49)*$C$28 -> -0.14330726 | O32: =-(N49)*$C$28 -> 0 | P32: =-(O49)*$C$28 -> 0
B33: 43100 | C33: =C32 -> 0.01 | J33: =-($C50)*$C$28*0.5 -> -1 | K33: =-(J50)*$C$28 -> -1.79 | L33: =-(K50)*$C$28 -> -1.3721 | M33: =-(L50)*$C$28 -> -0.958379 | N33: =-(M50)*$C$28 -> -0.54879521 | O33: =-(N50)*$C$28 -> -0.14330726 | P33: =-(O50)*$C$28 -> 0
B34: 43465 | C34: =C33 -> 0.01 | K34: =-($C51)*$C$28*0.5 -> -1 | L34: =-(K51)*$C$28 -> -1.79 | M34: =-(L51)*$C$28 -> -1.3721 | N34: =-(M51)*$C$28 -> -0.958379 | O34: =-(N51)*$C$28 -> -0.54879521 | P34: =-(O51)*$C$28 -> -0.14330726
B35: 43830 | C35: =C34 -> 0.01 | L35: =-($C52)*$C$28*0.5 -> -1 | M35: =-(L52)*$C$28 -> -1.79 | N35: =-(M52)*$C$28 -> -1.3721 | O35: =-(N52)*$C$28 -> -0.958379 | P35: =-(O52)*$C$28 -> -0.54879521
B36: 44196 | C36: =C35 -> 0.01 | M36: =-($C53)*$C$28*0.5 -> -1 | N36: =-(M53)*$C$28 -> -1.79 | O36: =-(N53)*$C$28 -> -1.3721 | P36: =-(O53)*$C$28 -> -0.958379
B37: 44561 | C37: =C36 -> 0.01 | N37: =-($C54)*$C$28*0.5 -> -1 | O37: =-(N54)*$C$28 -> -1.79 | P37: =-(O54)*$C$28 -> -1.3721
B38: 44926 | C38: =C37 -> 0.01 | O38: =-($C55)*$C$28*0.5 -> -1 | P38: =-(O55)*$C$28 -> -1.79
B39: 45291 | C39: =C38 -> 0.01 | P39: =-($C56)*$C$28*0.5 -> -1
B40: Total Net Credit Losses | E40: =SUM(E28:E39) -> -1 | F40: =SUM(F28:F39) -> -2.79 | G40: =SUM(G28:G39) -> -4.1621 | H40: =SUM(H28:H39) -> -5.120479 | I40: =SUM(I28:I39) -> -5.6692742 | J40: =SUM(J28:J39) -> -5.8125815 | K40: =SUM(K28:K39) -> -5.8125815 | L40: =SUM(L28:L39) -> -5.8125815 | ... P40: =SUM(P28:P39) -> -5.8125815
B42: Period-End Balance
C44: Origination
B45: {=TRANSPOSE($E$6:$P$6)} -> 41274 | C45: 200 | D45: 0 | E45: =$C45+E11+E28 -> 179 | F45: =E45+F11+F28 -> 137.21 | G45: =F45+G11+G28 -> 95.8379 | H45: =G45+H11+H28 -> 54.879521 | I45: =H45+I11+I28 -> 14.330726 | J45: =I45+J11+J28 -> 0 | K45: =J45+K11+K28 -> 0 | L45: =K45+L11+L28 -> 0 | M45: =L45+M11+M28 -> 0 | ... P45: =O45+P11+P28 -> 0
B46: 41639 | C46: =C45 -> 200 | E46: 0 | F46: =$C46+F12+F29 -> 179 | G46: =F46+G12+G29 -> 137.21 | H46: =G46+H12+H29 -> 95.8379 | I46: =H46+I12+I29 -> 54.879521 | J46: =I46+J12+J29 -> 14.330726 | K46: =J46+K12+K29 -> 0 | L46: =K46+L12+L29 -> 0 | M46: =L46+M12+M29 -> 0 | N46: =M46+N12+N29 -> 0 | ... P46: =O46+P12+P29 -> 0
B47: 42004 | C47: =C46 -> 200 | F47: 0 | G47: =$C47+G13+G30 -> 179 | H47: =G47+H13+H30 -> 137.21 | I47: =H47+I13+I30 -> 95.8379 | J47: =I47+J13+J30 -> 54.879521 | K47: =J47+K13+K30 -> 14.330726 | L47: =K47+L13+L30 -> 0 | M47: =L47+M13+M30 -> 0 | N47: =M47+N13+N30 -> 0 | O47: =N47+O13+O30 -> 0 | P47: =O47+P13+P30 -> 0
B48: 42369 | C48: =C47 -> 200 | G48: 0 | H48: =$C48+H14+H31 -> 179 | I48: =H48+I14+I31 -> 137.21 | J48: =I48+J14+J31 -> 95.8379 | K48: =J48+K14+K31 -> 54.879521 | L48: =K48+L14+L31 -> 14.330726 | M48: =L48+M14+M31 -> 0 | N48: =M48+N14+N31 -> 0 | O48: =N48+O14+O31 -> 0 | P48: =O48+P14+P31 -> 0
...

Sheet pres output
B1: Standard Operating Model
B2: Presentation Outputs
A4: x | L4: x
C5: Projected | K5: CAGR/
B6: ($MM, unless noted) | C6: 2013 | D6: =C6+1 -> 2014 | E6: =D6+1 -> 2015 | F6: =E6+1 -> 2016 | G6: =F6+1 -> 2017 | H6: =G6+1 -> 2018 | K6: Change
B8: Summary Balance Sheet
B9: Cash and Equivalents | C9: =model!F284 -> 482.25063 | D9: =model!H284 -> 647.71195 | E9: =model!I284 -> 664.37669 | F9: =model!J284 -> 678.12151 | G9: =model!K284 -> 689.5712 | H9: =model!L284 -> 699.21956 | K9: =RATE(5,0,-C9,G9)*100 -> 7.4140924
B10: Loans, Net | C10: =model!F289 -> 1444.5025 | D10: =model!H289 -> 2081.774 | E10: =model!I289 -> 2138.3515 | F10: =model!J289 -> 2183.0477 | G10: =model!K289 -> 2218.3577 | H10: =model!L289 -> 2246.2525 | K10: =RATE(5,0,-C10,G10)*100 -> 8.9588858
B11: Total Assets | C11: =model!F294 -> 2028.7531 | D11: =model!H294 -> 2891.6568 | E11: =model!I294 -> 2967.0214 | F11: =model!J294 -> 3027.6273 | G11: =model!K294 -> 3076.5951 | H11: =model!L294 -> 3116.3907 | K11: =RATE(5,0,-C11,G11)*100 -> 8.6846543
B12: Deposits | C12: =model!F305 -> 1575 | D12: =model!H305 -> 2336.4375 | E12: =model!I305 -> 2423.2594 | F12: =model!J305 -> 2514.4223 | G12: =model!K305 -> 2610.1435 | H12: =model!L305 -> 2710.6506 | K12: =RATE(5,0,-C12,G12)*100 -> 10.630981
B13: Common Equity | C13: =model!F274 -> 168.38745 | D13: =model!H274 -> 200.17396 | E13: =model!I274 -> 219.98828 | F13: =model!J274 -> 243.34383 | G13: =model!K274 -> 267.19715 | H13: =model!L274 -> 291.47773 | K13: =RATE(5,0,-C13,G13)*100 -> 9.6741862
B15: Summary Capitalization and Balance Sheet Metrics
B16: Tier 1 Ratio (%) | C16: =model!F319*100 -> 11.778022 | D16: =model!G319*100 -> 8.69485 | E16: =model!H319*100 -> 9.230191 | F16: =model!I319*100 -> 9.9178587 | G16: =model!J319*100 -> 10.784804 | H16: =model!K319*100 -> 11.684968 | K16: =H16-C16 -> -0.093054257
B17: Tier 1 Leverage (%) | C17: =model!F320*100 -> 8.3000465 | D17: =model!G320*100 -> 6.3400034 | E17: =model!H320*100 -> 6.7273186 | F17: =model!I320*100 -> 7.2252735 | G17: =model!J320*100 -> 7.8533099 | H17: =model!K320*100 -> 8.5049119 | K17: =H17-C17 -> 0.20486539
B18: Loans/Deposits (%) | C18: =C10/C12*100 -> 91.714444 | D18: =D10/D12*100 -> 89.100351 | E18: =E10/E12*100 -> 88.242781 | F18: =F10/F12*100 -> 86.821041 | G18: =G10/G12*100 -> 84.989874 | H18: =H10/H12*100 -> 82.867652 | K18: =H18-C18 -> -8.8467921
B20: Summary Income Statement and Performance Metrics
B21: Net Income | C21: =model!G252 -> 22.532122 | D21: =model!H252 -> 26.3702 | E21: =model!I252 -> 30.483566 | F21: =model!J252 -> 35.931609 | G21: =model!K252 -> 36.69743 | H21: =model!L252 -> 37.354736 | K21: =RATE(5,0,-C21,G21)*100 -> 10.246982
B22: Dividends | C22: =-(model!G270+model!G271) -> 7.8862426 | D22: =-(model!H270+model!H271) -> 9.22957 | E22: =-(model!I270+model!I271) -> 10.669248 | F22: =-(model!J270+model!J271) -> 12.576063 | G22: =-(model!K270+model!K271) -> 12.8441 | H22: =-(model!L270+model!L271) -> 13.074158 | K22: =RATE(5,0,-C22,G22)*100 -> 10.246982
B23: Net Interest Margin (%) | C23: =model!G311*100 -> 3.4538544 | D23: =model!H311*100 -> 3.4902087 | E23: =model!I311*100 -> 3.505303 | F23: =model!J311*100 -> 3.521112 | G23: =model!K311*100 -> 3.5376985 | H23: =model!L311*100 -> 3.5551107 | K23: =H23-C23 -> 0.10125635
B24: Fee Income Ratio (%) | C24: =model!G312*100 -> 20 | D24: =model!H312*100 -> 18.934197 | E24: =model!I312*100 -> 18.971039 | F24: =model!J312*100 -> 18.999893 | G24: =model!K312*100 -> 19.023058 | H24: =model!L312*100 -> 19.042101 | K24: =H24-C24 -> -0.95789913
B25: Efficiency Ratio (%) | C25: =model!G313*100 -> 60 | D25: =model!H313*100 -> 53.205509 | E25: =model!I313*100 -> 49.581771 | F25: =model!J313*100 -> 55.499519 | G25: =model!K313*100 -> 55.60376 | H25: =model!L313*100 -> 55.689454 | K25: =H25-C25 -> -4.3105461
B26: Return on Assets (%) | C26: =model!G314*100 -> 1.4677406 | D26: =model!H314*100 -> 1.1679475 | E26: =model!I314*100 -> 1.3171252 | F26: =model!J314*100 -> 1.5231082 | G26: =model!K314*100 -> 1.5326308 | H26: =model!L314*100 -> 1.5421169 | K26: =H26-C26 -> 0.074376292
B27: Return on Tangible Common Equity (%) | C27: =model!G316*100 -> 12.731211 | D27: =model!H316*100 -> 13.584207 | E27: =model!I316*100 -> 14.248767 | F27: =model!J316*100 -> 15.142244 | G27: =model!K316*100 -> 14.052395 | H27: =model!L316*100 -> 13.087283 | K27: =H27-C27 -> 0.35607209

Sheet chart output
B1: Standard Operating Model
B2: Presentation Outputs
B4: IRR Build-up:
B6: Base IRR | D6: 0 | E6: =F6-D6 -> 10.571286 | F6: =G6*100 -> 10.571286 | G6: =model!F376 -> 0.10571286
B7: Standalone Multiple Expansion | D7: =F6 -> 10.571286 | E7: =F7-D7 -> 2.7747047 | F7: =model!F378*100 -> 13.345991
B8: Standalone IRR | D8: 0 | E8: =F7 -> 13.345991
B9: Target Acquisition | D9: =E8 -> 13.345991 | E9: =F9-D9 -> 7.2391939 | F9: =model!M378*100 -> 20.585185
B10: Pro Forma IRR | D10: 0 | E10: =F9 -> 20.585185
